<mujoco model="nanosat">
  <compiler angle="radian" meshdir="assets" autolimits="true" texturedir="assets"/>

  <option integrator="implicitfast" gravity="0 0 0"/>

  <default>
    <default class="nanosat">
      <material specular="0.5" shininess="0.25"/>
    <default class="visual">
        <geom type="mesh" contype="0" conaffinity="0" group="2"/>
    </default>
    <default class="collision">
        <geom type="mesh" group="3"/>
      </default>
    </default>
  </default>

  <asset>
    <material name="Aluminium" specular="0.5" shininess="0.542231445" rgba="0.523579 0.523579 0.523579 1.000000"/>
    <material name="AluminiumAnodised" specular="0.5" shininess="0.542231445" rgba="0.636359 0.479112 0.229033 1.000000"/>
    <material name="AluminiumBlack" specular="0.5" shininess="0.542231445" rgba="0.086906 0.086906 0.086906 1.000000"/>
    <material name="AluminiumBlack.001" specular="0.5" shininess="0.542231445" rgba="0.086906 0.086906 0.086906 1.000000"/>
    <material name="AluminiumBlack.002" specular="0.5" shininess="0.542231445" rgba="0.086906 0.086906 0.086906 1.000000"/>
    <material name="AluminiumBlack.003" specular="0.5" shininess="0.542231445" rgba="0.086906 0.086906 0.086906 1.000000"/>
    <material name="AluminiumWhite" specular="0.5" shininess="0.386613068" rgba="0.850000 0.850000 0.850000 1.000000"/>
    <material name="Foil.Gold_2" specular="0.5" shininess="0.793881104" rgba="0.665500 0.337149 0.010959 1.000000"/>
    <texture type="2d" name="Foil_Gold_Color" file="Foil_Gold_Color.png"/>
    <material name="Foil.Gold_3" texture="Foil_Gold_Color" specular="0.5" shininess="0.25"/>
    <material name="Metal_1" specular="0.5" shininess="0.49" rgba="0.642848 0.642848 0.642848 1.000000"/>
    <material name="Metal_1.001" specular="0.5" shininess="0.49" rgba="0.642848 0.642848 0.642848 1.000000"/>
    <material name="Metal_1.002" specular="0.5" shininess="0.49" rgba="0.642848 0.642848 0.642848 1.000000"/>
    <material name="Metal_1.003" specular="0.5" shininess="0.49" rgba="0.642848 0.642848 0.642848 1.000000"/>
    <material name="PlasticWhite" specular="0.5" shininess="0.25" rgba="0.800000 0.800000 0.800000 1.000000"/>
    <texture type="2d" name="SolarCell.002_albedo" file="SolarCell.002_albedo.png"/>
    <material name="SolarCells_2" texture="SolarCell.002_albedo" specular="0.5" shininess="0.25"/>
    <texture type="2d" name="WPC_Diffuse" file="WPC_Diffuse.png"/>
    <material name="WhitePowderCoating" texture="WPC_Diffuse" specular="0.5" shininess="0.25"/>
    <mesh file="Nanosat_0.obj"/>
    <mesh file="Nanosat_1.obj"/>
    <mesh file="Nanosat_2.obj"/>
    <mesh file="Nanosat_3.obj"/>
    <mesh file="Nanosat_4.obj"/>
    <mesh file="Nanosat_5.obj"/>
    <mesh file="Nanosat_7.obj"/>
    <mesh file="Nanosat_8.obj"/>
    <mesh file="Nanosat_9.obj"/>
    <mesh file="Nanosat_10.obj"/>
    <mesh file="Nanosat_11.obj"/>
    <mesh file="Nanosat_12.obj"/>
    <mesh file="Nanosat_13.obj"/>
    <mesh file="Nanosat_14.obj"/>
    <mesh file="Nanosat_15.obj"/>
  </asset>
  <worldbody>
    <body name="Nanosat" childclass="nanosat">
      <freejoint/>
      <geom mesh="Nanosat_0" material="AluminiumBlack.003" class="visual"/>
      <geom mesh="Nanosat_1" material="Metal_1.003" class="visual"/>
      <geom mesh="Nanosat_2" material="AluminiumBlack.002" class="visual"/>
      <geom mesh="Nanosat_3" material="Metal_1.002" class="visual"/>
      <geom mesh="Nanosat_4" material="AluminiumBlack.001" class="visual"/>
      <geom mesh="Nanosat_5" material="Metal_1.001" class="visual"/>
      <geom mesh="Nanosat_7" material="Foil.Gold_2" class="visual"/>
      <geom mesh="Nanosat_8" material="SolarCells_2" class="visual"/>
      <geom mesh="Nanosat_9" material="AluminiumBlack" class="visual"/>
      <geom mesh="Nanosat_10" material="Metal_1" class="visual"/>
      <geom mesh="Nanosat_11" material="Foil.Gold_3" class="visual"/>
      <geom mesh="Nanosat_12" material="WhitePowderCoating" class="visual"/>
      <geom mesh="Nanosat_13" material="AluminiumAnodised" class="visual"/>
      <geom mesh="Nanosat_14" material="PlasticWhite" class="visual"/>
      <geom mesh="Nanosat_15" material="Aluminium" class="visual"/>
      <geom mesh="Nanosat_0" class="collision"/>
      <geom mesh="Nanosat_1" class="collision"/>
      <geom mesh="Nanosat_2" class="collision"/>
      <geom mesh="Nanosat_3" class="collision"/>
      <geom mesh="Nanosat_4" class="collision"/>
      <geom mesh="Nanosat_5" class="collision"/>
      <geom mesh="Nanosat_7" class="collision"/>
      <geom mesh="Nanosat_8" class="collision"/>
      <geom mesh="Nanosat_9" class="collision"/>
      <geom mesh="Nanosat_10" class="collision"/>
      <geom mesh="Nanosat_11" class="collision"/>
      <geom mesh="Nanosat_12" class="collision"/>
      <geom mesh="Nanosat_13" class="collision"/>
      <geom mesh="Nanosat_14" class="collision"/>
      <geom mesh="Nanosat_15" class="collision"/>
      <site name="thruster1" pos="0.04092 0.3 0.051802" size="0.01" rgba="1 0 0 0.5" type="sphere"/>
      <site name="thruster2" pos="-0.04092 0.3 0.051802" size="0.01" rgba="1 0 0 0.5" type="sphere"/>
      <site name="thruster3" pos="-0.04092 0.3 -0.051802" size="0.01" rgba="1 0 0 0.5" type="sphere"/>
      <site name="thruster4" pos="0.04092 0.3 -0.051802" size="0.01" rgba="1 0 0 0.5" type="sphere"/>
      <body name="RW_roll" pos="0 0.08 0" quat="0 0 -0.7071 0.7071">
        <joint name="rw_roll" type="hinge" axis="0 0 1" limited="false"/>
        <geom type="cylinder" size="0.06 0.01" pos="0 0 0" rgba="0 1 0 0.3" class="visual"/>
      </body>
      <body name="RW_pitch" pos="-0.08 0.15 0" quat="0 -0.7071 0 0.7071">
        <joint name="rw_pitch" type="hinge" axis="0 0 1" limited="false"/>
        <geom type="cylinder" size="0.06 0.01" pos="0 0 0" rgba="0 1 0 0.3" class="visual"/>
      </body>
      <body name="RW_yaw" pos="0 0.15 0.08" quat="0 0 0 1">
        <joint name="rw_yaw" type="hinge" axis="0 0 1" limited="false"/>
        <geom type="cylinder" size="0.06 0.01" pos="0 0 0" rgba="0 1 0 0.3" class="visual"/>
      </body>
    </body>
  </worldbody>

  <actuator>
    <general name="RW_roll" joint="rw_roll" ctrllimited="true" ctrlrange="-0.5 0.5"/>
    <general name="RW_pitch" joint="rw_pitch" ctrllimited="true" ctrlrange="-0.5 0.5"/>
    <general name="RW_yaw" joint="rw_yaw" ctrllimited="true" ctrlrange="-0.5 0.5"/>
    <general name="thruster1" site="thruster1" class="nanosat" gear="0 -1 0" ctrllimited="true" ctrlrange="0 1"/>
    <general name="thruster2" site="thruster2" class="nanosat" gear="0 -1 0" ctrllimited="true" ctrlrange="0 1"/>
    <general name="thruster3" site="thruster3" class="nanosat" gear="0 -1 0" ctrllimited="true" ctrlrange="0 1"/>
    <general name="thruster4" site="thruster4" class="nanosat" gear="0 -1 0" ctrllimited="true" ctrlrange="0 1"/>
  </actuator>

  <keyframe>
    <key name="home" qpos="0 0 0 0 0 0 1 0 0 0"/>
  </keyframe>
</mujoco>